[2023-04-25T13:22:06.486+0000] {taskinstance.py:1165} INFO - Dependencies all met for <TaskInstance: user_processing.process_user manual__2023-04-25T13:22:05.173640+00:00 [queued]>
[2023-04-25T13:22:06.496+0000] {taskinstance.py:1165} INFO - Dependencies all met for <TaskInstance: user_processing.process_user manual__2023-04-25T13:22:05.173640+00:00 [queued]>
[2023-04-25T13:22:06.498+0000] {taskinstance.py:1362} INFO - 
--------------------------------------------------------------------------------
[2023-04-25T13:22:06.498+0000] {taskinstance.py:1363} INFO - Starting attempt 1 of 1
[2023-04-25T13:22:06.499+0000] {taskinstance.py:1364} INFO - 
--------------------------------------------------------------------------------
[2023-04-25T13:22:06.517+0000] {taskinstance.py:1383} INFO - Executing <Task(PythonOperator): process_user> on 2023-04-25 13:22:05.173640+00:00
[2023-04-25T13:22:06.525+0000] {standard_task_runner.py:55} INFO - Started process 13496 to run task
[2023-04-25T13:22:06.543+0000] {standard_task_runner.py:82} INFO - Running: ['***', 'tasks', 'run', 'user_processing', 'process_user', 'manual__2023-04-25T13:22:05.173640+00:00', '--job-id', '57', '--raw', '--subdir', 'DAGS_FOLDER/user_processing.py', '--cfg-path', '/tmp/tmpftezqd1g']
[2023-04-25T13:22:06.557+0000] {standard_task_runner.py:83} INFO - Job 57: Subtask process_user
[2023-04-25T13:22:06.700+0000] {task_command.py:376} INFO - Running <TaskInstance: user_processing.process_user manual__2023-04-25T13:22:05.173640+00:00 [running]> on host bebb68623a17
[2023-04-25T13:22:06.830+0000] {taskinstance.py:1592} INFO - Exporting the following env vars:
AIRFLOW_CTX_DAG_OWNER=***
AIRFLOW_CTX_DAG_ID=user_processing
AIRFLOW_CTX_TASK_ID=process_user
AIRFLOW_CTX_EXECUTION_DATE=2023-04-25T13:22:05.173640+00:00
AIRFLOW_CTX_TRY_NUMBER=1
AIRFLOW_CTX_DAG_RUN_ID=manual__2023-04-25T13:22:05.173640+00:00
[2023-04-25T13:22:06.832+0000] {taskinstance.py:1851} ERROR - Task failed with exception
Traceback (most recent call last):
  File "/home/airflow/.local/lib/python3.7/site-packages/airflow/operators/python.py", line 175, in execute
    return_value = self.execute_callable()
  File "/home/airflow/.local/lib/python3.7/site-packages/airflow/operators/python.py", line 193, in execute_callable
    return self.python_callable(*self.op_args, **self.op_kwargs)
TypeError: _process_user() missing 1 required positional argument: 'kwargs'
[2023-04-25T13:22:06.843+0000] {taskinstance.py:1406} INFO - Marking task as FAILED. dag_id=user_processing, task_id=process_user, execution_date=20230425T132205, start_date=20230425T132206, end_date=20230425T132206
[2023-04-25T13:22:06.853+0000] {standard_task_runner.py:105} ERROR - Failed to execute job 57 for task process_user (_process_user() missing 1 required positional argument: 'kwargs'; 13496)
[2023-04-25T13:22:06.877+0000] {local_task_job.py:164} INFO - Task exited with return code 1
[2023-04-25T13:22:06.893+0000] {local_task_job.py:273} INFO - 0 downstream tasks scheduled from follow-on schedule check
