[2023-04-26T11:42:00.989+0000] {taskinstance.py:1165} INFO - Dependencies all met for <TaskInstance: slack_dag.dummy_task scheduled__2023-04-25T00:00:00+00:00 [queued]>
[2023-04-26T11:42:00.996+0000] {taskinstance.py:1165} INFO - Dependencies all met for <TaskInstance: slack_dag.dummy_task scheduled__2023-04-25T00:00:00+00:00 [queued]>
[2023-04-26T11:42:00.996+0000] {taskinstance.py:1362} INFO - 
--------------------------------------------------------------------------------
[2023-04-26T11:42:00.997+0000] {taskinstance.py:1363} INFO - Starting attempt 1 of 1
[2023-04-26T11:42:00.997+0000] {taskinstance.py:1364} INFO - 
--------------------------------------------------------------------------------
[2023-04-26T11:42:01.004+0000] {taskinstance.py:1383} INFO - Executing <Task(PythonOperator): dummy_task> on 2023-04-25 00:00:00+00:00
[2023-04-26T11:42:01.010+0000] {standard_task_runner.py:55} INFO - Started process 2623 to run task
[2023-04-26T11:42:01.013+0000] {standard_task_runner.py:82} INFO - Running: ['***', 'tasks', 'run', 'slack_dag', 'dummy_task', 'scheduled__2023-04-25T00:00:00+00:00', '--job-id', '280', '--raw', '--subdir', 'DAGS_FOLDER/dag3.py', '--cfg-path', '/tmp/tmpks16vmqh']
[2023-04-26T11:42:01.014+0000] {standard_task_runner.py:83} INFO - Job 280: Subtask dummy_task
[2023-04-26T11:42:01.062+0000] {task_command.py:376} INFO - Running <TaskInstance: slack_dag.dummy_task scheduled__2023-04-25T00:00:00+00:00 [running]> on host 641cb7472cb1
[2023-04-26T11:42:01.110+0000] {taskinstance.py:1592} INFO - Exporting the following env vars:
AIRFLOW_CTX_DAG_OWNER=***
AIRFLOW_CTX_DAG_ID=slack_dag
AIRFLOW_CTX_TASK_ID=dummy_task
AIRFLOW_CTX_EXECUTION_DATE=2023-04-25T00:00:00+00:00
AIRFLOW_CTX_TRY_NUMBER=1
AIRFLOW_CTX_DAG_RUN_ID=scheduled__2023-04-25T00:00:00+00:00
[2023-04-26T11:42:01.111+0000] {taskinstance.py:1851} ERROR - Task failed with exception
Traceback (most recent call last):
  File "/home/airflow/.local/lib/python3.7/site-packages/airflow/operators/python.py", line 175, in execute
    return_value = self.execute_callable()
  File "/home/airflow/.local/lib/python3.7/site-packages/airflow/operators/python.py", line 193, in execute_callable
    return self.python_callable(*self.op_args, **self.op_kwargs)
  File "/opt/airflow/dags/dag3.py", line 11, in dummyConditionalTask
    raise Exception()
Exception
[2023-04-26T11:42:01.121+0000] {taskinstance.py:1406} INFO - Marking task as FAILED. dag_id=slack_dag, task_id=dummy_task, execution_date=20230425T000000, start_date=20230426T114200, end_date=20230426T114201
[2023-04-26T11:42:01.129+0000] {standard_task_runner.py:105} ERROR - Failed to execute job 280 for task dummy_task (; 2623)
[2023-04-26T11:42:01.145+0000] {local_task_job.py:164} INFO - Task exited with return code 1
[2023-04-26T11:42:01.166+0000] {local_task_job.py:273} INFO - 1 downstream tasks scheduled from follow-on schedule check
