[2023-04-25T13:00:44.045+0000] {taskinstance.py:1165} INFO - Dependencies all met for <TaskInstance: user_processing.process_user manual__2023-04-25T13:00:42.983415+00:00 [queued]>
[2023-04-25T13:00:44.055+0000] {taskinstance.py:1165} INFO - Dependencies all met for <TaskInstance: user_processing.process_user manual__2023-04-25T13:00:42.983415+00:00 [queued]>
[2023-04-25T13:00:44.056+0000] {taskinstance.py:1362} INFO - 
--------------------------------------------------------------------------------
[2023-04-25T13:00:44.056+0000] {taskinstance.py:1363} INFO - Starting attempt 1 of 1
[2023-04-25T13:00:44.057+0000] {taskinstance.py:1364} INFO - 
--------------------------------------------------------------------------------
[2023-04-25T13:00:44.067+0000] {taskinstance.py:1383} INFO - Executing <Task(PythonOperator): process_user> on 2023-04-25 13:00:42.983415+00:00
[2023-04-25T13:00:44.075+0000] {standard_task_runner.py:55} INFO - Started process 12380 to run task
[2023-04-25T13:00:44.081+0000] {standard_task_runner.py:82} INFO - Running: ['***', 'tasks', 'run', 'user_processing', 'process_user', 'manual__2023-04-25T13:00:42.983415+00:00', '--job-id', '39', '--raw', '--subdir', 'DAGS_FOLDER/user_processing.py', '--cfg-path', '/tmp/tmpew_gef7f']
[2023-04-25T13:00:44.082+0000] {standard_task_runner.py:83} INFO - Job 39: Subtask process_user
[2023-04-25T13:00:44.168+0000] {task_command.py:376} INFO - Running <TaskInstance: user_processing.process_user manual__2023-04-25T13:00:42.983415+00:00 [running]> on host bebb68623a17
[2023-04-25T13:00:44.252+0000] {taskinstance.py:1592} INFO - Exporting the following env vars:
AIRFLOW_CTX_DAG_OWNER=***
AIRFLOW_CTX_DAG_ID=user_processing
AIRFLOW_CTX_TASK_ID=process_user
AIRFLOW_CTX_EXECUTION_DATE=2023-04-25T13:00:42.983415+00:00
AIRFLOW_CTX_TRY_NUMBER=1
AIRFLOW_CTX_DAG_RUN_ID=manual__2023-04-25T13:00:42.983415+00:00
[2023-04-25T13:00:44.265+0000] {taskinstance.py:1851} ERROR - Task failed with exception
Traceback (most recent call last):
  File "/home/airflow/.local/lib/python3.7/site-packages/airflow/operators/python.py", line 175, in execute
    return_value = self.execute_callable()
  File "/home/airflow/.local/lib/python3.7/site-packages/airflow/operators/python.py", line 193, in execute_callable
    return self.python_callable(*self.op_args, **self.op_kwargs)
  File "/opt/airflow/dags/user_processing.py", line 12, in _process_user
    user = res['results'][0]
TypeError: 'NoneType' object is not subscriptable
[2023-04-25T13:00:44.278+0000] {taskinstance.py:1406} INFO - Marking task as FAILED. dag_id=user_processing, task_id=process_user, execution_date=20230425T130042, start_date=20230425T130044, end_date=20230425T130044
[2023-04-25T13:00:44.285+0000] {standard_task_runner.py:105} ERROR - Failed to execute job 39 for task process_user ('NoneType' object is not subscriptable; 12380)
[2023-04-25T13:00:44.330+0000] {local_task_job.py:164} INFO - Task exited with return code 1
[2023-04-25T13:00:44.348+0000] {local_task_job.py:273} INFO - 0 downstream tasks scheduled from follow-on schedule check
