[2023-04-25T10:32:42.056+0000] {taskinstance.py:1165} INFO - Dependencies all met for <TaskInstance: user_processing.create_table scheduled__2023-04-24T00:00:00+00:00 [queued]>
[2023-04-25T10:32:42.064+0000] {taskinstance.py:1165} INFO - Dependencies all met for <TaskInstance: user_processing.create_table scheduled__2023-04-24T00:00:00+00:00 [queued]>
[2023-04-25T10:32:42.064+0000] {taskinstance.py:1362} INFO - 
--------------------------------------------------------------------------------
[2023-04-25T10:32:42.065+0000] {taskinstance.py:1363} INFO - Starting attempt 1 of 1
[2023-04-25T10:32:42.066+0000] {taskinstance.py:1364} INFO - 
--------------------------------------------------------------------------------
[2023-04-25T10:32:42.076+0000] {taskinstance.py:1383} INFO - Executing <Task(PostgresOperator): create_table> on 2023-04-24 00:00:00+00:00
[2023-04-25T10:32:42.083+0000] {standard_task_runner.py:55} INFO - Started process 6543 to run task
[2023-04-25T10:32:42.087+0000] {standard_task_runner.py:82} INFO - Running: ['***', 'tasks', 'run', 'user_processing', 'create_table', 'scheduled__2023-04-24T00:00:00+00:00', '--job-id', '10', '--raw', '--subdir', 'DAGS_FOLDER/user_processing.py', '--cfg-path', '/tmp/tmpgpti_uuh']
[2023-04-25T10:32:42.088+0000] {standard_task_runner.py:83} INFO - Job 10: Subtask create_table
[2023-04-25T10:32:42.163+0000] {task_command.py:376} INFO - Running <TaskInstance: user_processing.create_table scheduled__2023-04-24T00:00:00+00:00 [running]> on host bebb68623a17
[2023-04-25T10:32:42.241+0000] {taskinstance.py:1592} INFO - Exporting the following env vars:
AIRFLOW_CTX_DAG_OWNER=***
AIRFLOW_CTX_DAG_ID=user_processing
AIRFLOW_CTX_TASK_ID=create_table
AIRFLOW_CTX_EXECUTION_DATE=2023-04-24T00:00:00+00:00
AIRFLOW_CTX_TRY_NUMBER=1
AIRFLOW_CTX_DAG_RUN_ID=scheduled__2023-04-24T00:00:00+00:00
[2023-04-25T10:32:42.255+0000] {base.py:71} INFO - Using connection ID 'postgres' for task execution.
[2023-04-25T10:32:42.271+0000] {taskinstance.py:1851} ERROR - Task failed with exception
Traceback (most recent call last):
  File "/home/airflow/.local/lib/python3.7/site-packages/airflow/providers/postgres/operators/postgres.py", line 94, in execute
    self.hook.run(self.sql, self.autocommit, parameters=self.parameters)
  File "/home/airflow/.local/lib/python3.7/site-packages/airflow/providers/common/sql/hooks/sql.py", line 288, in run
    with closing(self.get_conn()) as conn:
  File "/home/airflow/.local/lib/python3.7/site-packages/airflow/providers/postgres/hooks/postgres.py", line 115, in get_conn
    self.conn = psycopg2.connect(**conn_args)
  File "/home/airflow/.local/lib/python3.7/site-packages/psycopg2/__init__.py", line 122, in connect
    conn = _connect(dsn, connection_factory=connection_factory, **kwasync)
psycopg2.OperationalError: connection to server at "postgres" (172.19.0.3), port 5432 failed: FATAL:  password authentication failed for user "***"

[2023-04-25T10:32:42.291+0000] {taskinstance.py:1406} INFO - Marking task as FAILED. dag_id=user_processing, task_id=create_table, execution_date=20230424T000000, start_date=20230425T103242, end_date=20230425T103242
[2023-04-25T10:32:42.298+0000] {standard_task_runner.py:105} ERROR - Failed to execute job 10 for task create_table (connection to server at "postgres" (172.19.0.3), port 5432 failed: FATAL:  password authentication failed for user "***"
; 6543)
[2023-04-25T10:32:42.342+0000] {local_task_job.py:164} INFO - Task exited with return code 1
[2023-04-25T10:32:42.357+0000] {local_task_job.py:273} INFO - 0 downstream tasks scheduled from follow-on schedule check
